Workbook
Name operas: Performances!$A$1:$I$56

Sheet Performances
A1: Date | B1: Time | C1: OperaName | D1: AlternateTitle | E1: Composer | F1: Language | G1: OperaCompany | H1: Venue | I1: Seats
A2: 38493 | C2: Carmen | D2: =_xlfn.XLOOKUP($C2,Operas!$A:$A,Operas!B:B,"",0,1)&"" | E2: =_xlfn.XLOOKUP($C2,Operas!$A:$A,Operas!C:C,"",0,1)&"" -> Georges Bizet | F2: =_xlfn.XLOOKUP($C2,Operas!$A:$A,Operas!D:D,"",0,1)&"" -> French | G2: Opéra de Montréal | H2: =_xlfn.XLOOKUP(G2,Companies!A:A,Companies!B:B,"",0,-1)&"" -> Place des Arts
A3: 41720 | C3: Hansel & Gretel | D3: =_xlfn.XLOOKUP($C3,Operas!$A:$A,Operas!B:B,"",0,1)&"" | E3: =_xlfn.XLOOKUP($C3,Operas!$A:$A,Operas!C:C,"",0,1)&"" -> Engelbert Humperdinck | F3: =_xlfn.XLOOKUP($C3,Operas!$A:$A,Operas!D:D,"",0,1)&"" -> German | G3: Opéra de Montréal | H3: =_xlfn.XLOOKUP(G3,Companies!A:A,Companies!B:B,"",0,-1)&"" -> Place des Arts
A4: 42139 | B4: 19:30 | C4: La Traviata | D4: =_xlfn.XLOOKUP($C4,Operas!$A:$A,Operas!B:B,"",0,1)&"" | E4: =_xlfn.XLOOKUP($C4,Operas!$A:$A,Operas!C:C,"",0,1)&"" -> Giuseppe Verdi | F4: =_xlfn.XLOOKUP($C4,Operas!$A:$A,Operas!D:D,"",0,1)&"" -> Italian | G4: Staatstheater Nürnberg | H4: =_xlfn.XLOOKUP(G4,Companies!A:A,Companies!B:B,"",0,-1)&"" -> Opernhaus Nürnberg
A5: 42160 | B5: 20:00 | C5: Salome | D5: =_xlfn.XLOOKUP($C5,Operas!$A:$A,Operas!B:B,"",0,1)&"" | E5: =_xlfn.XLOOKUP($C5,Operas!$A:$A,Operas!C:C,"",0,1)&"" -> Richard Strauss | F5: =_xlfn.XLOOKUP($C5,Operas!$A:$A,Operas!D:D,"",0,1)&"" -> German | G5: Wiener Staatsoper | H5: =_xlfn.XLOOKUP(G5,Companies!A:A,Companies!B:B,"",0,-1)&"" -> Wiener Staatsoper
A6: 42659 | B6: 14:00 | C6: Ariodante | D6: =_xlfn.XLOOKUP($C6,Operas!$A:$A,Operas!B:B,"",0,1)&"" | E6: =_xlfn.XLOOKUP($C6,Operas!$A:$A,Operas!C:C,"",0,1)&"" -> George Frideric Handel | F6: =_xlfn.XLOOKUP($C6,Operas!$A:$A,Operas!D:D,"",0,1)&"" -> Italian | G6: Canadian Opera Company | H6: =_xlfn.XLOOKUP(G6,Companies!A:A,Companies!B:B,"",0,-1)&"" -> Four Seasons Centre for the Performing Arts | I6: H554
A7: 42669 | B7: 19:30 | C7: Norma | D7: =_xlfn.XLOOKUP($C7,Operas!$A:$A,Operas!B:B,"",0,1)&"" | E7: =_xlfn.XLOOKUP($C7,Operas!$A:$A,Operas!C:C,"",0,1)&"" -> Vincenzo Bellini | F7: =_xlfn.XLOOKUP($C7,Operas!$A:$A,Operas!D:D,"",0,1)&"" -> Italian | G7: Canadian Opera Company | H7: =_xlfn.XLOOKUP(G7,Companies!A:A,Companies!B:B,"",0,-1)&"" -> Four Seasons Centre for the Performing Arts | I7: H512
A8: 42768 | B8: 18:00 | C8: Götterdämmerung | D8: =_xlfn.XLOOKUP($C8,Operas!$A:$A,Operas!B:B,"",0,1)&"" | E8: =_xlfn.XLOOKUP($C8,Operas!$A:$A,Operas!C:C,"",0,1)&"" -> Richard Wagner | F8: =_xlfn.XLOOKUP($C8,Operas!$A:$A,Operas!D:D,"",0,1)&"" -> German | G8: Canadian Opera Company | H8: =_xlfn.XLOOKUP(G8,Companies!A:A,Companies!B:B,"",0,-1)&"" -> Four Seasons Centre for the Performing Arts | I8: G526
A9: 42776 | B9: 19:30 | C9: The Magic Flute | D9: =_xlfn.XLOOKUP($C9,Operas!$A:$A,Operas!B:B,"",0,1)&"" -> Die Zauberflöte | E9: =_xlfn.XLOOKUP($C9,Operas!$A:$A,Operas!C:C,"",0,1)&"" -> Wolfgang Amadeus Mozart | F9: =_xlfn.XLOOKUP($C9,Operas!$A:$A,Operas!D:D,"",0,1)&"" -> German | G9: Canadian Opera Company | H9: =_xlfn.XLOOKUP(G9,Companies!A:A,Companies!B:B,"",0,-1)&"" -> Four Seasons Centre for the Performing Arts | I9: C556
A10: 42868 | B10: 20:30 | C10: Cyrano de Bergerac | D10: =_xlfn.XLOOKUP($C10,Operas!$A:$A,Operas!B:B,"",0,1)&"" | E10: =_xlfn.XLOOKUP($C10,Operas!$A:$A,Operas!C:C,"",0,1)&"" -> Franco Alfano | F10: =_xlfn.XLOOKUP($C10,Operas!$A:$A,Operas!D:D,"",0,1)&"" -> French | G10: Metropolitan Opera | H10: =_xlfn.XLOOKUP(G10,Companies!A:A,Companies!B:B,"",0,-1)&"" -> Metropolitan Opera House | I10: DRESS CIRCLE B26
A11: 43013 | B11: 19:30 | C11: Arabella | D11: =_xlfn.XLOOKUP($C11,Operas!$A:$A,Operas!B:B,"",0,1)&"" | E11: =_xlfn.XLOOKUP($C11,Operas!$A:$A,Operas!C:C,"",0,1)&"" -> Richard Strauss | F11: =_xlfn.XLOOKUP($C11,Operas!$A:$A,Operas!D:D,"",0,1)&"" -> German | G11: Canadian Opera Company | H11: =_xlfn.XLOOKUP(G11,Companies!A:A,Companies!B:B,"",0,-1)&"" -> Four Seasons Centre for the Performing Arts | I11: G533-G534-G535
A12: 43041 | B12: 19:30 | C12: The Elixir of Love | D12: =_xlfn.XLOOKUP($C12,Operas!$A:$A,Operas!B:B,"",0,1)&"" -> L'elisir d'amore | E12: =_xlfn.XLOOKUP($C12,Operas!$A:$A,Operas!C:C,"",0,1)&"" -> Gaetano Donizetti | F12: =_xlfn.XLOOKUP($C12,Operas!$A:$A,Operas!D:D,"",0,1)&"" -> Italian | G12: Canadian Opera Company | H12: =_xlfn.XLOOKUP(G12,Companies!A:A,Companies!B:B,"",0,-1)&"" -> Four Seasons Centre for the Performing Arts | I12: H522
A13: 43140 | B13: 19:30 | C13: Rigoletto | D13: =_xlfn.XLOOKUP($C13,Operas!$A:$A,Operas!B:B,"",0,1)&"" | E13: =_xlfn.XLOOKUP($C13,Operas!$A:$A,Operas!C:C,"",0,1)&"" -> Giuseppe Verdi | F13: =_xlfn.XLOOKUP($C13,Operas!$A:$A,Operas!D:D,"",0,1)&"" -> Italian | G13: Canadian Opera Company | H13: =_xlfn.XLOOKUP(G13,Companies!A:A,Companies!B:B,"",0,-1)&"" -> Four Seasons Centre for the Performing Arts | I13: G550-G551-G552-H552-H553-H554-H555
A14: 43144 | B14: 19:30 | C14: The Abduction from the Seraglio | D14: =_xlfn.XLOOKUP($C14,Operas!$A:$A,Operas!B:B,"",0,1)&"" -> Die Entführung aus dem Serail | E14: =_xlfn.XLOOKUP($C14,Operas!$A:$A,Operas!C:C,"",0,1)&"" -> Wolfgang Amadeus Mozart | F14: =_xlfn.XLOOKUP($C14,Operas!$A:$A,Operas!D:D,"",0,1)&"" -> German | G14: Canadian Opera Company | H14: =_xlfn.XLOOKUP(G14,Companies!A:A,Companies!B:B,"",0,-1)&"" -> Four Seasons Centre for the Performing Arts | I14: G533-G534
A15: 43246 | B15: 19:30 | C15: Anna Bolena | D15: =_xlfn.XLOOKUP($C15,Operas!$A:$A,Operas!B:B,"",0,1)&"" | E15: =_xlfn.XLOOKUP($C15,Operas!$A:$A,Operas!C:C,"",0,1)&"" -> Gaetano Donizetti | F15: =_xlfn.XLOOKUP($C15,Operas!$A:$A,Operas!D:D,"",0,1)&"" -> Italian | G15: Canadian Opera Company | H15: =_xlfn.XLOOKUP(G15,Companies!A:A,Companies!B:B,"",0,-1)&"" -> Four Seasons Centre for the Performing Arts | I15: H515-H516-H517
A16: 43501 | B16: 19:30 | C16: Così fan tutte | D16: =_xlfn.XLOOKUP($C16,Operas!$A:$A,Operas!B:B,"",0,1)&"" | E16: =_xlfn.XLOOKUP($C16,Operas!$A:$A,Operas!C:C,"",0,1)&"" -> Wolfgang Amadeus Mozart | F16: =_xlfn.XLOOKUP($C16,Operas!$A:$A,Operas!D:D,"",0,1)&"" -> Italian | G16: Canadian Opera Company | H16: =_xlfn.XLOOKUP(G16,Companies!A:A,Companies!B:B,"",0,-1)&"" -> Four Seasons Centre for the Performing Arts | I16: H547-H548
A17: 43572 | B17: 19:30 | C17: La Bohème | D17: =_xlfn.XLOOKUP($C17,Operas!$A:$A,Operas!B:B,"",0,1)&"" | E17: =_xlfn.XLOOKUP($C17,Operas!$A:$A,Operas!C:C,"",0,1)&"" -> Giacomo Puccini | F17: =_xlfn.XLOOKUP($C17,Operas!$A:$A,Operas!D:D,"",0,1)&"" -> Italian | G17: Canadian Opera Company | H17: =_xlfn.XLOOKUP(G17,Companies!A:A,Companies!B:B,"",0,-1)&"" -> Four Seasons Centre for the Performing Arts
A18: 43594 | B18: 19:30 | C18: Otello | D18: =_xlfn.XLOOKUP($C18,Operas!$A:$A,Operas!B:B,"",0,1)&"" | E18: =_xlfn.XLOOKUP($C18,Operas!$A:$A,Operas!C:C,"",0,1)&"" -> Giuseppe Verdi | F18: =_xlfn.XLOOKUP($C18,Operas!$A:$A,Operas!D:D,"",0,1)&"" -> Italian | G18: Canadian Opera Company | H18: =_xlfn.XLOOKUP(G18,Companies!A:A,Companies!B:B,"",0,-1)&"" -> Four Seasons Centre for the Performing Arts
A19: 43747 | B19: 19:30 | C19: Turandot | D19: =_xlfn.XLOOKUP($C19,Operas!$A:$A,Operas!B:B,"",0,1)&"" | E19: =_xlfn.XLOOKUP($C19,Operas!$A:$A,Operas!C:C,"",0,1)&"" -> Giacomo Puccini | F19: =_xlfn.XLOOKUP($C19,Operas!$A:$A,Operas!D:D,"",0,1)&"" -> Italian | G19: Canadian Opera Company | H19: =_xlfn.XLOOKUP(G19,Companies!A:A,Companies!B:B,"",0,-1)&"" -> Four Seasons Centre for the Performing Arts
A20: 43754 | B20: 19:30 | C20: Rusalka | D20: =_xlfn.XLOOKUP($C20,Operas!$A:$A,Operas!B:B,"",0,1)&"" | E20: =_xlfn.XLOOKUP($C20,Operas!$A:$A,Operas!C:C,"",0,1)&"" -> Antonín Dvořák | F20: =_xlfn.XLOOKUP($C20,Operas!$A:$A,Operas!D:D,"",0,1)&"" -> Czech | G20: Canadian Opera Company | H20: =_xlfn.XLOOKUP(G20,Companies!A:A,Companies!B:B,"",0,-1)&"" -> Four Seasons Centre for the Performing Arts
A21: 43852 | B21: 0.8125 | C21: The Barber of Seville | D21: =_xlfn.XLOOKUP($C21,Operas!$A:$A,Operas!B:B,"",0,1)&"" -> Il barbiere di Siviglia | E21: =_xlfn.XLOOKUP($C21,Operas!$A:$A,Operas!C:C,"",0,1)&"" -> Gioachino Rossini | F21: =_xlfn.XLOOKUP($C21,Operas!$A:$A,Operas!D:D,"",0,1)&"" -> Italian | G21: Canadian Opera Company | H21: =_xlfn.XLOOKUP(G21,Companies!A:A,Companies!B:B,"",0,-1)&"" -> Four Seasons Centre for the Performing Arts
A22: 43882 | B22: 19:30 | C22: Hansel & Gretel | D22: =_xlfn.XLOOKUP($C22,Operas!$A:$A,Operas!B:B,"",0,1)&"" | E22: =_xlfn.XLOOKUP($C22,Operas!$A:$A,Operas!C:C,"",0,1)&"" -> Engelbert Humperdinck | F22: =_xlfn.XLOOKUP($C22,Operas!$A:$A,Operas!D:D,"",0,1)&"" -> German | G22: Canadian Opera Company | H22: =_xlfn.XLOOKUP(G22,Companies!A:A,Companies!B:B,"",0,-1)&"" -> Four Seasons Centre for the Performing Arts
A23: 44682 | B23: 14:00 | C23: La Traviata | D23: =_xlfn.XLOOKUP($C23,Operas!$A:$A,Operas!B:B,"",0,1)&"" | E23: =_xlfn.XLOOKUP($C23,Operas!$A:$A,Operas!C:C,"",0,1)&"" -> Giuseppe Verdi | F23: =_xlfn.XLOOKUP($C23,Operas!$A:$A,Operas!D:D,"",0,1)&"" -> Italian | G23: Canadian Opera Company | H23: =_xlfn.XLOOKUP(G23,Companies!A:A,Companies!B:B,"",0,-1)&"" -> Four Seasons Centre for the Performing Arts | I23: A516
A24: 44689 | B24: 14:00 | C24: The Magic Flute | D24: =_xlfn.XLOOKUP($C24,Operas!$A:$A,Operas!B:B,"",0,1)&"" -> Die Zauberflöte | E24: =_xlfn.XLOOKUP($C24,Operas!$A:$A,Operas!C:C,"",0,1)&"" -> Wolfgang Amadeus Mozart | F24: =_xlfn.XLOOKUP($C24,Operas!$A:$A,Operas!D:D,"",0,1)&"" -> German | G24: Canadian Opera Company | H24: =_xlfn.XLOOKUP(G24,Companies!A:A,Companies!B:B,"",0,-1)&"" -> Four Seasons Centre for the Performing Arts | I24: A516
A25: 44857 | B25: 14:00 | C25: The Flying Dutchman | D25: =_xlfn.XLOOKUP($C25,Operas!$A:$A,Operas!B:B,"",0,1)&"" -> Der fliegende Holländer | E25: =_xlfn.XLOOKUP($C25,Operas!$A:$A,Operas!C:C,"",0,1)&"" -> Richard Wagner | F25: =_xlfn.XLOOKUP($C25,Operas!$A:$A,Operas!D:D,"",0,1)&"" -> German | G25: Canadian Opera Company | H25: =_xlfn.XLOOKUP(G25,Companies!A:A,Companies!B:B,"",0,-1)&"" -> Four Seasons Centre for the Performing Arts | I25: A513
A26: 44869 | B26: 19:30 | C26: Carmen | D26: =_xlfn.XLOOKUP($C26,Operas!$A:$A,Operas!B:B,"",0,1)&"" | E26: =_xlfn.XLOOKUP($C26,Operas!$A:$A,Operas!C:C,"",0,1)&"" -> Georges Bizet | F26: =_xlfn.XLOOKUP($C26,Operas!$A:$A,Operas!D:D,"",0,1)&"" -> French | G26: Canadian Opera Company | H26: =_xlfn.XLOOKUP(G26,Companies!A:A,Companies!B:B,"",0,-1)&"" -> Four Seasons Centre for the Performing Arts | I26: A562
A27: 44967 | B27: 19:30 | C27: The Marriage of Figaro | D27: =_xlfn.XLOOKUP($C27,Operas!$A:$A,Operas!B:B,"",0,1)&"" -> Le nozze di Figaro | E27: =_xlfn.XLOOKUP($C27,Operas!$A:$A,Operas!C:C,"",0,1)&"" -> Wolfgang Amadeus Mozart | F27: =_xlfn.XLOOKUP($C27,Operas!$A:$A,Operas!D:D,"",0,1)&"" -> Italian | G27: Canadian Opera Company | H27: =_xlfn.XLOOKUP(G27,Companies!A:A,Companies!B:B,"",0,-1)&"" -> Four Seasons Centre for the Performing Arts | I27: A548
A28: 44981 | B28: 19:30 | C28: Salome | D28: =_xlfn.XLOOKUP($C28,Operas!$A:$A,Operas!B:B,"",0,1)&"" | E28: =_xlfn.XLOOKUP($C28,Operas!$A:$A,Operas!C:C,"",0,1)&"" -> Richard Strauss | F28: =_xlfn.XLOOKUP($C28,Operas!$A:$A,Operas!D:D,"",0,1)&"" -> German | G28: Canadian Opera Company | H28: =_xlfn.XLOOKUP(G28,Companies!A:A,Companies!B:B,"",0,-1)&"" -> Four Seasons Centre for the Performing Arts | I28: A512
A29: 45046 | B29: 14:00 | C29: Macbeth | D29: =_xlfn.XLOOKUP($C29,Operas!$A:$A,Operas!B:B,"",0,1)&"" | E29: =_xlfn.XLOOKUP($C29,Operas!$A:$A,Operas!C:C,"",0,1)&"" -> Giuseppe Verdi | F29: =_xlfn.XLOOKUP($C29,Operas!$A:$A,Operas!D:D,"",0,1)&"" -> Italian | G29: Canadian Opera Company | H29: =_xlfn.XLOOKUP(G29,Companies!A:A,Companies!B:B,"",0,-1)&"" -> Four Seasons Centre for the Performing Arts | I29: A516
A30: 45067 | B30: 14:00 | C30: Tosca | D30: =_xlfn.XLOOKUP($C30,Operas!$A:$A,Operas!B:B,"",0,1)&"" | E30: =_xlfn.XLOOKUP($C30,Operas!$A:$A,Operas!C:C,"",0,1)&"" -> Giacomo Puccini | F30: =_xlfn.XLOOKUP($C30,Operas!$A:$A,Operas!D:D,"",0,1)&"" -> Italian | G30: Canadian Opera Company | H30: =_xlfn.XLOOKUP(G30,Companies!A:A,Companies!B:B,"",0,-1)&"" -> Four Seasons Centre for the Performing Arts | I30: A516
A31: 45207 | B31: 14:00 | C31: La Bohème | D31: =_xlfn.XLOOKUP($C31,Operas!$A:$A,Operas!B:B,"",0,1)&"" | E31: =_xlfn.XLOOKUP($C31,Operas!$A:$A,Operas!C:C,"",0,1)&"" -> Giacomo Puccini | F31: =_xlfn.XLOOKUP($C31,Operas!$A:$A,Operas!D:D,"",0,1)&"" -> Italian | G31: Canadian Opera Company | H31: =_xlfn.XLOOKUP(G31,Companies!A:A,Companies!B:B,"",0,-1)&"" -> Four Seasons Centre for the Performing Arts | I31: A516
A32: 45213 | B32: 16:30 | C32: Fidelio | D32: =_xlfn.XLOOKUP($C32,Operas!$A:$A,Operas!B:B,"",0,1)&"" | E32: =_xlfn.XLOOKUP($C32,Operas!$A:$A,Operas!C:C,"",0,1)&"" -> Ludwig van Beethoven | F32: =_xlfn.XLOOKUP($C32,Operas!$A:$A,Operas!D:D,"",0,1)&"" -> German | G32: Canadian Opera Company | H32: =_xlfn.XLOOKUP(G32,Companies!A:A,Companies!B:B,"",0,-1)&"" -> Four Seasons Centre for the Performing Arts | I32: B507
A33: 45317 | B33: 19:30 | C33: The Cunning Little Vixen | D33: =_xlfn.XLOOKUP($C33,Operas!$A:$A,Operas!B:B,"",0,1)&"" -> Příhody lišky Bystroušky | E33: =_xlfn.XLOOKUP($C33,Operas!$A:$A,Operas!C:C,"",0,1)&"" -> Leoš Janáček | F33: =_xlfn.XLOOKUP($C33,Operas!$A:$A,Operas!D:D,"",0,1)&"" -> Czech | G33: Canadian Opera Company | H33: =_xlfn.XLOOKUP(G33,Companies!A:A,Companies!B:B,"",0,-1)&"" -> Four Seasons Centre for the Performing Arts | I33: B505
A34: 45326 | B34: 14:00 | C34: Don Giovanni | D34: =_xlfn.XLOOKUP($C34,Operas!$A:$A,Operas!B:B,"",0,1)&"" | E34: =_xlfn.XLOOKUP($C34,Operas!$A:$A,Operas!C:C,"",0,1)&"" -> Wolfgang Amadeus Mozart | F34: =_xlfn.XLOOKUP($C34,Operas!$A:$A,Operas!D:D,"",0,1)&"" -> Italian | G34: Canadian Opera Company | H34: =_xlfn.XLOOKUP(G34,Companies!A:A,Companies!B:B,"",0,-1)&"" -> Four Seasons Centre for the Performing Arts | I34: A516
... A56: 46523 | B56: 14:00 | C56: The Elixir of Love | D56: =_xlfn.XLOOKUP($C56,Operas!$A:$A,Operas!B:B,"",0,1)&"" -> L'elisir d'amore | E56: =_xlfn.XLOOKUP($C56,Operas!$A:$A,Operas!C:C,"",0,1)&"" -> Gaetano Donizetti | F56: =_xlfn.XLOOKUP($C56,Operas!$A:$A,Operas!D:D,"",0,1)&"" -> Italian | G56: Canadian Opera Company | H56: =_xlfn.XLOOKUP(G56,Companies!A:A,Companies!B:B,"",0,-1)&"" -> Four Seasons Centre for the Performing Arts | I56: A516

Sheet Operas
A1: OperaName | B1: AlternateTitle | C1: Composer | D1: Language
A2: Carmen | C2: Georges Bizet | D2: French
A3: Hansel & Gretel | C3: Engelbert Humperdinck | D3: German
A4: La Traviata | C4: Giuseppe Verdi | D4: Italian
A5: Salome | C5: Richard Strauss | D5: German
A6: Ariodante | C6: George Frideric Handel | D6: Italian
A7: Norma | C7: Vincenzo Bellini | D7: Italian
A8: Götterdämmerung | C8: Richard Wagner | D8: German
A9: The Magic Flute | B9: Die Zauberflöte | C9: Wolfgang Amadeus Mozart | D9: German
A10: Cyrano de Bergerac | C10: Franco Alfano | D10: French
A11: Arabella | C11: Richard Strauss | D11: German
A12: The Elixir of Love | B12: L'elisir d'amore | C12: Gaetano Donizetti | D12: Italian
A13: Rigoletto | C13: Giuseppe Verdi | D13: Italian
A14: The Abduction from the Seraglio | B14: Die Entführung aus dem Serail | C14: Wolfgang Amadeus Mozart | D14: German
A15: Anna Bolena | C15: Gaetano Donizetti | D15: Italian
A16: Così fan tutte | C16: Wolfgang Amadeus Mozart | D16: Italian
A17: La Bohème | C17: Giacomo Puccini | D17: Italian
A18: Otello | C18: Giuseppe Verdi | D18: Italian
A19: Turandot | C19: Giacomo Puccini | D19: Italian
A20: Rusalka | C20: Antonín Dvořák | D20: Czech
A21: The Barber of Seville | B21: Il barbiere di Siviglia | C21: Gioachino Rossini | D21: Italian
A22: The Flying Dutchman | B22: Der fliegende Holländer | C22: Richard Wagner | D22: German
A23: The Marriage of Figaro | B23: Le nozze di Figaro | C23: Wolfgang Amadeus Mozart | D23: Italian
A24: Macbeth | C24: Giuseppe Verdi | D24: Italian
A25: Tosca | C25: Giacomo Puccini | D25: Italian
A26: Fidelio | C26: Ludwig van Beethoven | D26: German
A27: The Cunning Little Vixen | B27: Příhody lišky Bystroušky | C27: Leoš Janáček | D27: Czech
A28: Don Giovanni | C28: Wolfgang Amadeus Mozart | D28: Italian
A29: Medea | C29: Luigi Cherubini | D29: Italian
A30: Don Pasquale | C30: Gaetano Donizetti | D30: Italian
A31: Nabucco | C31: Giuseppe Verdi | D31: Italian
A32: Faust | C32: Charles Gounod | D32: French
A33: Madama Butterfly | C33: Giacomo Puccini | D33: Italian
A34: La Reine-garçon | C34: Julien Bilodeau | D34: French
A35: Wozzeck | C35: Alban Berg | D35: German
A36: Eugene Onegin | C36: Pyotr Ilyich Tchaikovsky | D36: Russian
A37: Cavalleria rusticana | C37: Pietro Mascagni | D37: Italian
A38: Romeo and Juliet | B38: Roméo et Juliette | C38: Charles Gounod | D38: French
A39: Orfeo ed Euridice | C39: Christoph Willibald Gluck | D39: Italian
A40: Bluebeard’s Castle | C40: Béla Bartók | D40: Hungarian
...

Sheet Companies
A1: OperaCompany | B1: Venue | H1: {=_xlfn.UNIQUE(Performances!G:G,FALSE,FALSE)&""} -> OperaCompany | I1: =_xlfn.XLOOKUP(H1,Performances!G:G,Performances!H:H,"",0,-1)&"" -> Venue
A2: Opéra de Montréal | B2: Place des Arts | H2: Opéra de Montréal | I2: =_xlfn.XLOOKUP(H2,Performances!G:G,Performances!H:H,"",0,-1)&"" -> Place des Arts
A3: Staatstheater Nürnberg | B3: Opernhaus Nürnberg | H3: Staatstheater Nürnberg | I3: =_xlfn.XLOOKUP(H3,Performances!G:G,Performances!H:H,"",0,-1)&"" -> Opernhaus Nürnberg
A4: Wiener Staatsoper | B4: Wiener Staatsoper | H4: Wiener Staatsoper | I4: =_xlfn.XLOOKUP(H4,Performances!G:G,Performances!H:H,"",0,-1)&"" -> Wiener Staatsoper
A5: Canadian Opera Company | B5: Four Seasons Centre for the Performing Arts | H5: Canadian Opera Company | I5: =_xlfn.XLOOKUP(H5,Performances!G:G,Performances!H:H,"",0,-1)&"" -> Four Seasons Centre for the Performing Arts
A6: Metropolitan Opera | B6: Metropolitan Opera House | H6: Metropolitan Opera | I6: =_xlfn.XLOOKUP(H6,Performances!G:G,Performances!H:H,"",0,-1)&"" -> Metropolitan Opera House
